2021-12-15 13:33:19,782 - Exception occurred
Traceback (most recent call last):
  File "C:\Users\ollym\Desktop\python_project\app\covid_data_handler.py", line 35, in <module>
    with open("app/static/json/config.json") as config_file:
FileNotFoundError: [Errno 2] No such file or directory: 'app/static/json/config.json'
2021-12-15 13:34:36,235 - Trying to load test file
NoneType: None
2021-12-15 13:39:08,241 - Trying to load test file
NoneType: None
2021-12-15 13:39:08,242 - Exception occurred
Traceback (most recent call last):
  File "C:\Users\ollym\Desktop\python_project\app\covid_data_handler.py", line 25, in <module>
    with open("app/static/json/config.json") as config_file:
FileNotFoundError: [Errno 2] No such file or directory: 'app/static/json/config.json'
2021-12-15 13:44:05,320 - Trying to load test file
NoneType: None
2021-12-15 13:44:05,321 - Exception occurred
Traceback (most recent call last):
  File "C:\Users\ollym\Desktop\python_project\app\covid_data_handler.py", line 25, in <module>
    with open("app/static/json/config.json") as config_file:
FileNotFoundError: [Errno 2] No such file or directory: 'app/static/json/config.json'
2021-12-15 13:44:15,474 - Trying to load test file
NoneType: None
